Traceback (most recent call last):
  File "/Users/tompkins/Library/Python/3.10/lib/python/site-packages/jupyter_cache/executors/utils.py", line 51, in single_nb_execution
    executenb(
  File "/Users/tompkins/Library/Python/3.10/lib/python/site-packages/nbclient/client.py", line 1204, in execute
    return NotebookClient(nb=nb, resources=resources, km=km, **kwargs).execute()
  File "/Users/tompkins/Library/Python/3.10/lib/python/site-packages/nbclient/util.py", line 84, in wrapped
    return just_run(coro(*args, **kwargs))
  File "/Users/tompkins/Library/Python/3.10/lib/python/site-packages/nbclient/util.py", line 62, in just_run
    return loop.run_until_complete(coro)
  File "/usr/local/Cellar/python@3.10/3.10.13_1/Frameworks/Python.framework/Versions/3.10/lib/python3.10/asyncio/base_events.py", line 649, in run_until_complete
    return future.result()
  File "/Users/tompkins/Library/Python/3.10/lib/python/site-packages/nbclient/client.py", line 663, in async_execute
    await self.async_execute_cell(
  File "/Users/tompkins/Library/Python/3.10/lib/python/site-packages/nbclient/client.py", line 965, in async_execute_cell
    await self._check_raise_for_error(cell, cell_index, exec_reply)
  File "/Users/tompkins/Library/Python/3.10/lib/python/site-packages/nbclient/client.py", line 862, in _check_raise_for_error
    raise CellExecutionError.from_cell_and_msg(cell, exec_reply_content)
nbclient.exceptions.CellExecutionError: An error occurred while executing the following cell:
------------------
import cdsapi
c = cdsapi.Client()

from netCDF4 import Dataset,num2date
import matplotlib.pyplot as plt
import cartopy.crs as ccrs
import cartopy.feature as cfea
import cartopy.util as cutil
import matplotlib as mplt
import numpy as np
from mpl_toolkits.axes_grid1 import make_axes_locatable
from cdo import Cdo
import os 
cdo=Cdo()
scr="/Users/tompkins/Downloads/"
------------------

[0;31m---------------------------------------------------------------------------[0m
[0;31mModuleNotFoundError[0m                       Traceback (most recent call last)
Cell [0;32mIn[1], line 6[0m
[1;32m      4[0m [38;5;28;01mfrom[39;00m [38;5;21;01mnetCDF4[39;00m [38;5;28;01mimport[39;00m Dataset,num2date
[1;32m      5[0m [38;5;28;01mimport[39;00m [38;5;21;01mmatplotlib[39;00m[38;5;21;01m.[39;00m[38;5;21;01mpyplot[39;00m [38;5;28;01mas[39;00m [38;5;21;01mplt[39;00m
[0;32m----> 6[0m [38;5;28;01mimport[39;00m [38;5;21;01mcartopy[39;00m[38;5;21;01m.[39;00m[38;5;21;01mcrs[39;00m [38;5;28;01mas[39;00m [38;5;21;01mccrs[39;00m
[1;32m      7[0m [38;5;28;01mimport[39;00m [38;5;21;01mcartopy[39;00m[38;5;21;01m.[39;00m[38;5;21;01mfeature[39;00m [38;5;28;01mas[39;00m [38;5;21;01mcfea[39;00m
[1;32m      8[0m [38;5;28;01mimport[39;00m [38;5;21;01mcartopy[39;00m[38;5;21;01m.[39;00m[38;5;21;01mutil[39;00m [38;5;28;01mas[39;00m [38;5;21;01mcutil[39;00m

[0;31mModuleNotFoundError[0m: No module named 'cartopy'
ModuleNotFoundError: No module named 'cartopy'

